Traceback (most recent call last):
  File "/Users/lillythomas/.pyenv/versions/3.9.0/envs/py39b/lib/python3.9/site-packages/jupyter_cache/executors/utils.py", line 58, in single_nb_execution
    executenb(
  File "/Users/lillythomas/.pyenv/versions/3.9.0/envs/py39b/lib/python3.9/site-packages/nbclient/client.py", line 1314, in execute
    return NotebookClient(nb=nb, resources=resources, km=km, **kwargs).execute()
  File "/Users/lillythomas/.pyenv/versions/3.9.0/envs/py39b/lib/python3.9/site-packages/jupyter_core/utils/__init__.py", line 165, in wrapped
    return loop.run_until_complete(inner)
  File "/Users/lillythomas/.pyenv/versions/3.9.0/lib/python3.9/asyncio/base_events.py", line 642, in run_until_complete
    return future.result()
  File "/Users/lillythomas/.pyenv/versions/3.9.0/envs/py39b/lib/python3.9/site-packages/nbclient/client.py", line 709, in async_execute
    await self.async_execute_cell(
  File "/Users/lillythomas/.pyenv/versions/3.9.0/envs/py39b/lib/python3.9/site-packages/nbclient/client.py", line 1062, in async_execute_cell
    await self._check_raise_for_error(cell, cell_index, exec_reply)
  File "/Users/lillythomas/.pyenv/versions/3.9.0/envs/py39b/lib/python3.9/site-packages/nbclient/client.py", line 918, in _check_raise_for_error
    raise CellExecutionError.from_cell_and_msg(cell, exec_reply_content)
nbclient.exceptions.CellExecutionError: An error occurred while executing the following cell:
------------------
import dask
import geopandas as gpd
import odc.stac
import math
import matplotlib.pyplot as plt
import matplotlib.colors as mcolors
import numpy as np
import pystac_client
import rasterio
import requests
import rioxarray
import time
import xarray as xr
from geocube.api.core import make_geocube
from geopandas import GeoSeries, GeoDataFrame
from lonboard import Map, PolygonLayer, viz
from pyproj import CRS
from rasterstats import zonal_stats
from shapely.geometry import box, Point, shape
from tqdm.auto import tqdm
------------------


[0;31m---------------------------------------------------------------------------[0m
[0;31mModuleNotFoundError[0m                       Traceback (most recent call last)
Cell [0;32mIn[2], line 14[0m
[1;32m     12[0m [38;5;28;01mimport[39;00m [38;5;21;01mtime[39;00m
[1;32m     13[0m [38;5;28;01mimport[39;00m [38;5;21;01mxarray[39;00m [38;5;28;01mas[39;00m [38;5;21;01mxr[39;00m
[0;32m---> 14[0m [38;5;28;01mfrom[39;00m [38;5;21;01mgeocube[39;00m[38;5;21;01m.[39;00m[38;5;21;01mapi[39;00m[38;5;21;01m.[39;00m[38;5;21;01mcore[39;00m [38;5;28;01mimport[39;00m make_geocube
[1;32m     15[0m [38;5;28;01mfrom[39;00m [38;5;21;01mgeopandas[39;00m [38;5;28;01mimport[39;00m GeoSeries, GeoDataFrame
[1;32m     16[0m [38;5;28;01mfrom[39;00m [38;5;21;01mlonboard[39;00m [38;5;28;01mimport[39;00m Map, PolygonLayer, viz

[0;31mModuleNotFoundError[0m: No module named 'geocube'

